Workbook
Name Dropship_Cost_Per_Unit: #REF!
Name Sim_Cost_Inflation: #REF!
Name Sim_Fix_Negative: #REF!
Name Target_Margin_Pct: #REF!

Sheet 01_Data_Mart_Raw
A1: consolidated_sku | B1: product_name | C1: category | D1: catalog_integration_status | E1: retail_price | F1: current_supplier_cost | G1: current_unit_margin_amount | H1: current_margin_percentage | I1: margin_health_status | J1: internal_stock | K1: reorder_point | L1: supplier_stock | M1: total_system_availability | N1: stock_health_status | O1: recommended_fulfillment_route | P1: duplicate_name
A2: SKU-9991 | D2: SUPPLIER ONLY | F2: 25.48 | I2: N/A Missing price data | J2: 0 | K2: 15 | L2: 29 | M2: 29 | N2: CRITICAL Internal stockout - reorder available from Supplier | O2: Fulfill via dropship | P2: =IF(COUNTIF($B$2:$B$506, B2)>1, "DUPLICATE", "OK") -> OK
A3: SKU-9992 | D3: SUPPLIER ONLY | F3: 92.67 | I3: N/A Missing price data | J3: 0 | K3: 15 | L3: 191 | M3: 191 | N3: CRITICAL Internal stockout - reorder available from Supplier | O3: Fulfill via dropship | P3: =IF(COUNTIF($B$2:$B$506, B3)>1, "DUPLICATE", "OK") -> OK
A4: SKU-9993 | D4: SUPPLIER ONLY | F4: 49.53 | I4: N/A Missing price data | J4: 0 | K4: 15 | L4: 200 | M4: 200 | N4: CRITICAL Internal stockout - reorder available from Supplier | O4: Fulfill via dropship | P4: =IF(COUNTIF($B$2:$B$506, B4)>1, "DUPLICATE", "OK") -> OK
A5: SKU-9994 | D5: SUPPLIER ONLY | F5: 24.97 | I5: N/A Missing price data | J5: 0 | K5: 15 | L5: 32 | M5: 32 | N5: CRITICAL Internal stockout - reorder available from Supplier | O5: Fulfill via dropship | P5: =IF(COUNTIF($B$2:$B$506, B5)>1, "DUPLICATE", "OK") -> OK
A6: SKU-9995 | D6: SUPPLIER ONLY | F6: 101.87 | I6: N/A Missing price data | J6: 0 | K6: 15 | L6: 128 | M6: 128 | N6: CRITICAL Internal stockout - reorder available from Supplier | O6: Fulfill via dropship | P6: =IF(COUNTIF($B$2:$B$506, B6)>1, "DUPLICATE", "OK") -> OK
A7: SKU-1001 | B7: Harry Potter Complete Box Set 2024 Edition | C7: Books | D7: MATCHED | E7: 78.31 | F7: 25.34 | G7: 52.97 | H7: 0.6764 | I7: MARGIN OK | J7: 33 | K7: 15 | L7: 44 | M7: 77 | N7: HEALTHY AVAILABILITY Internal available stock | O7: Fulfill in-house | P7: =IF(COUNTIF($B$2:$B$506, B7)>1, "DUPLICATE", "OK") -> OK
A8: SKU-1002 | B8: Samsung Galaxy S24 - Coral | C8: Electronics | D8: MATCHED | E8: 822.58 | F8: 287.7 | G8: 534.88 | H8: 0.6502 | I8: MARGIN OK | J8: 32 | K8: 15 | L8: 136 | M8: 168 | N8: HEALTHY AVAILABILITY Internal available stock | O8: Fulfill in-house | P8: =IF(COUNTIF($B$2:$B$506, B8)>1, "DUPLICATE", "OK") -> OK
A9: SKU-1003 | B9: Sony WH-1000XM5 Headphones Large | C9: Electronics | D9: MATCHED | E9: 363.55 | F9: 126.68 | G9: 236.87 | H9: 0.6515 | I9: MARGIN OK | J9: 46 | K9: 15 | L9: 461 | M9: 507 | N9: HEALTHY AVAILABILITY Internal available stock | O9: Fulfill in-house | P9: =IF(COUNTIF($B$2:$B$506, B9)>1, "DUPLICATE", "OK") -> OK
A10: SKU-1004 | B10: Nerf Elite Disruptor Blaster Premium - Coral | C10: Toys | D10: MATCHED | E10: 20.85 | F10: 14.46 | G10: 6.39 | H10: 0.3065 | I10: MARGIN OK | J10: 16 | K10: 15 | L10: 194 | M10: 210 | N10: HEALTHY AVAILABILITY Internal available stock | O10: Fulfill in-house | P10: =IF(COUNTIF($B$2:$B$506, B10)>1, "DUPLICATE", "OK") -> OK
A11: SKU-1005 | B11: Keychron K2 Mechanical Keyboard X-Large - Ivory | C11: Electronics | D11: MATCHED | E11: 104.84 | F11: 56.75 | G11: 48.09 | H11: 0.4587 | I11: MARGIN OK | J11: 92 | K11: 15 | L11: 170 | M11: 262 | N11: HEALTHY AVAILABILITY Internal available stock | O11: Fulfill in-house | P11: =IF(COUNTIF($B$2:$B$506, B11)>1, "DUPLICATE", "OK") -> OK
A12: SKU-1006 | B12: Dell UltraSharp 27 Monitor Performance | C12: Electronics | D12: MATCHED | E12: 490.43 | F12: 199.23 | G12: 291.2 | H12: 0.5938 | I12: MARGIN OK | J12: 88 | K12: 15 | L12: 26 | M12: 114 | N12: HEALTHY AVAILABILITY Internal available stock | O12: Fulfill in-house | P12: =IF(COUNTIF($B$2:$B$506, B12)>1, "DUPLICATE", "OK") -> OK
A13: SKU-1007 | B13: Melissa & Doug Wooden Train Set - Navy | C13: Toys | D13: MATCHED | E13: 54.23 | F13: 20.17 | G13: 34.06 | H13: 0.6281 | I13: MARGIN OK | J13: 97 | K13: 15 | L13: 172 | M13: 269 | N13: HEALTHY AVAILABILITY Internal available stock | O13: Fulfill in-house | P13: =IF(COUNTIF($B$2:$B$506, B13)>1, "DUPLICATE", "OK") -> OK
A14: SKU-1008 | B14: Garmin Forerunner 265 Smartwatch Set of 2 | C14: Electronics | D14: MATCHED | E14: 353.83 | F14: 195.47 | G14: 158.36 | H14: 0.4476 | I14: MARGIN OK | J14: 83 | K14: 15 | L14: 359 | M14: 442 | N14: HEALTHY AVAILABILITY Internal available stock | O14: Fulfill in-house | P14: =IF(COUNTIF($B$2:$B$506, B14)>1, "DUPLICATE", "OK") -> OK
A15: SKU-1009 | B15: Anker 65W USB-C Charger Premium - Cream | C15: Electronics | D15: MATCHED | E15: 36.93 | F15: 15.15 | G15: 21.78 | H15: 0.5898 | I15: MARGIN OK | J15: 16 | K15: 15 | L15: 0 | M15: 16 | N15: HEALTHY AVAILABILITY Internal available stock | O15: Fulfill in-house | P15: =IF(COUNTIF($B$2:$B$506, B15)>1, "DUPLICATE", "OK") -> OK
A16: SKU-1010 | B16: Canon EOS R50 Camera 2L - Lavender | C16: Electronics | D16: MATCHED | E16: 519.78 | F16: 286.44 | G16: 233.34 | H16: 0.4489 | I16: MARGIN OK | J16: 34 | K16: 15 | L16: 396 | M16: 430 | N16: HEALTHY AVAILABILITY Internal available stock | O16: Fulfill in-house | P16: =IF(COUNTIF($B$2:$B$506, B16)>1, "DUPLICATE", "OK") -> OK
A17: SKU-1011 | B17: JBL Flip 6 Bluetooth Speaker Studio | C17: Electronics | D17: MATCHED | E17: 140.56 | F17: 47.71 | G17: 92.85 | H17: 0.6606 | I17: MARGIN OK | J17: 61 | K17: 15 | L17: 305 | M17: 366 | N17: HEALTHY AVAILABILITY Internal available stock | O17: Fulfill in-house | P17: =IF(COUNTIF($B$2:$B$506, B17)>1, "DUPLICATE", "OK") -> OK
A18: SKU-1012 | B18: Canon EOS R50 Camera - Olive | C18: Electronics | D18: MATCHED | E18: 575.18 | F18: 220.68 | G18: 354.5 | H18: 0.6163 | I18: MARGIN OK | J18: 57 | K18: 15 | L18: 3 | M18: 60 | N18: HEALTHY AVAILABILITY Internal available stock | O18: Fulfill in-house | P18: =IF(COUNTIF($B$2:$B$506, B18)>1, "DUPLICATE", "OK") -> OK
A19: SKU-1013 | B19: The Great Gatsby - Paperback Pack of 5 | C19: Books | D19: MATCHED | F19: 6.59 | I19: N/A Missing price data | J19: 85 | K19: 15 | L19: 229 | M19: 314 | N19: HEALTHY AVAILABILITY Internal available stock | O19: Fulfill in-house | P19: =IF(COUNTIF($B$2:$B$506, B19)>1, "DUPLICATE", "OK") -> OK
A20: SKU-1014 | B20: Amazon Echo Dot 5th Gen Standard - Ivory | C20: Electronics | D20: MATCHED | E20: 51.31 | F20: 17.75 | G20: 33.56 | H20: 0.6541 | I20: MARGIN OK | J20: 83 | K20: 15 | L20: 22 | M20: 105 | N20: HEALTHY AVAILABILITY Internal available stock | O20: Fulfill in-house | P20: =IF(COUNTIF($B$2:$B$506, B20)>1, "DUPLICATE", "OK") -> OK
A21: SKU-1015 | B21: Google Nest Hub 2nd Gen Pack of 5 - Lavender | C21: Electronics | D21: MATCHED | E21: 91.71 | F21: 31.34 | G21: 60.37 | H21: 0.6583 | I21: MARGIN OK | J21: 31 | K21: 15 | L21: 72 | M21: 103 | N21: HEALTHY AVAILABILITY Internal available stock | O21: Fulfill in-house | P21: =IF(COUNTIF($B$2:$B$506, B21)>1, "DUPLICATE", "OK") -> OK
A22: SKU-1016 | B22: Artificial Monstera Plant Essential | C22: Home | D22: MATCHED | E22: 29.72 | F22: 10.6 | G22: 19.12 | H22: 0.6433 | I22: MARGIN OK | J22: 94 | K22: 15 | L22: 464 | M22: 558 | N22: HEALTHY AVAILABILITY Internal available stock | O22: Fulfill in-house | P22: =IF(COUNTIF($B$2:$B$506, B22)>1, "DUPLICATE", "OK") -> OK
A23: SKU-1017 | B23: Arduino Uno R4 WiFi - Teal | C23: Electronics | D23: MATCHED | E23: 26.08 | F23: 8.07 | G23: 18.01 | H23: 0.6906 | I23: MARGIN OK | J23: 36 | K23: 15 | L23: 466 | M23: 502 | N23: HEALTHY AVAILABILITY Internal available stock | O23: Fulfill in-house | P23: =IF(COUNTIF($B$2:$B$506, B23)>1, "DUPLICATE", "OK") -> OK
A24: SKU-1018 | B24: Logitech C920 HD Webcam 750ml | C24: Electronics | D24: MATCHED | E24: 74.79 | F24: 36.93 | G24: 37.86 | H24: 0.5062 | I24: MARGIN OK | J24: 46 | K24: 15 | L24: 244 | M24: 290 | N24: HEALTHY AVAILABILITY Internal available stock | O24: Fulfill in-house | P24: =IF(COUNTIF($B$2:$B$506, B24)>1, "DUPLICATE", "OK") -> OK
A25: SKU-1019 | B25: Baby Einstein Activity Gym Ultra - Gray | C25: Toys | D25: MATCHED | E25: 41.39 | F25: 17.36 | G25: 24.03 | H25: 0.5806 | I25: MARGIN OK | J25: 42 | K25: 15 | L25: 428 | M25: 470 | N25: HEALTHY AVAILABILITY Internal available stock | O25: Fulfill in-house | P25: =IF(COUNTIF($B$2:$B$506, B25)>1, "DUPLICATE", "OK") -> OK
A26: SKU-1020 | B26: Philips Hue White Bulb Pack of 5 - White | C26: Electronics | D26: MATCHED | E26: 16.56 | F26: 5.27 | G26: 11.29 | H26: 0.6818 | I26: MARGIN OK | J26: 15 | K26: 15 | L26: 156 | M26: 171 | N26: WARNING Below reorder point - reorder available from Supplier | O26: Fulfill in-house | P26: =IF(COUNTIF($B$2:$B$506, B26)>1, "DUPLICATE", "OK") -> OK
A27: SKU-1021 | B27: Fitbit Charge 6 Digital | C27: Electronics | D27: MATCHED | E27: 148.07 | F27: 67.31 | G27: 80.76 | H27: 0.5454 | I27: MARGIN OK | J27: 86 | K27: 15 | L27: 410 | M27: 496 | N27: HEALTHY AVAILABILITY Internal available stock | O27: Fulfill in-house | P27: =IF(COUNTIF($B$2:$B$506, B27)>1, "DUPLICATE", "OK") -> DUPLICATE
A28: SKU-1022 | B28: Cotton Crew Neck T-Shirt - Graphite | C28: Clothing | D28: MATCHED | E28: 18.94 | F28: 9.8 | G28: 9.14 | H28: 0.4826 | I28: MARGIN OK | J28: 81 | K28: 15 | L28: 420 | M28: 501 | N28: HEALTHY AVAILABILITY Internal available stock | O28: Fulfill in-house | P28: =IF(COUNTIF($B$2:$B$506, B28)>1, "DUPLICATE", "OK") -> OK
A29: SKU-1023 | B29: Nintendo Switch OLED Small | C29: Electronics | D29: MATCHED | E29: 349 | F29: 200.33 | G29: 148.67 | H29: 0.426 | I29: MARGIN OK | J29: 78 | K29: 15 | L29: 269 | M29: 347 | N29: HEALTHY AVAILABILITY Internal available stock | O29: Fulfill in-house | P29: =IF(COUNTIF($B$2:$B$506, B29)>1, "DUPLICATE", "OK") -> DUPLICATE
A30: SKU-1024 | B30: Steam Deck OLED 512GB Analog - Ivory | C30: Electronics | D30: MATCHED | E30: 549 | F30: 241.12 | G30: 307.88 | H30: 0.5608 | I30: MARGIN OK | J30: 2 | K30: 15 | L30: 491 | M30: 493 | N30: WARNING Below reorder point - reorder available from Supplier | O30: Fulfill in-house | P30: =IF(COUNTIF($B$2:$B$506, B30)>1, "DUPLICATE", "OK") -> OK
A31: SKU-1025 | B31: Giro Bicycle Helmet 400g - Slate | C31: Sports | D31: MATCHED | E31: 67.73 | F31: 29.93 | G31: 37.8 | H31: 0.5581 | I31: MARGIN OK | J31: 23 | K31: 15 | L31: 203 | M31: 226 | N31: HEALTHY AVAILABILITY Internal available stock | O31: Fulfill in-house | P31: =IF(COUNTIF($B$2:$B$506, B31)>1, "DUPLICATE", "OK") -> OK
... A63: SKU-1057 | B63: Minimalist Wall Clock - Black | C63: Home | D63: MATCHED | E63: 49.93 | F63: 36.43 | G63: 13.5 | H63: 0.2704 | I63: MARGIN OK | J63: 83 | K63: 15 | L63: 324 | M63: 407 | N63: HEALTHY AVAILABILITY Internal available stock | O63: Fulfill in-house | P63: =IF(COUNTIF($B$2:$B$506, B63)>1, "DUPLICATE", "OK") -> OK
A64: SKU-1058 | B64: Baby Einstein Activity Gym 400g | C64: Toys | D64: MATCHED | F64: 19.17 | I64: N/A Missing price data | J64: 77 | K64: 15 | L64: 55 | M64: 132 | N64: HEALTHY AVAILABILITY Internal available stock | O64: Fulfill in-house | P64: =IF(COUNTIF($B$2:$B$506, B64)>1, "DUPLICATE", "OK") -> OK
A65: SKU-1059 | B65: Scented Soy Candle Studio - Blue | C65: Home | D65: MATCHED | E65: 19.7 | F65: 11.38 | G65: 8.32 | H65: 0.4223 | I65: MARGIN OK | J65: 94 | K65: 15 | L65: 261 | M65: 355 | N65: HEALTHY AVAILABILITY Internal available stock | O65: Fulfill in-house | P65: =IF(COUNTIF($B$2:$B$506, B65)>1, "DUPLICATE", "OK") -> OK
A66: SKU-1060 | B66: Bamboo Drawer Organizer Set of 6 - Navy | C66: Home | D66: MATCHED | E66: 21.72 | F66: 9.99 | G66: 11.73 | H66: 0.5401 | I66: MARGIN OK | J66: 2 | K66: 15 | L66: 45 | M66: 47 | N66: WARNING Below reorder point - reorder available from Supplier | O66: Fulfill in-house | P66: =IF(COUNTIF($B$2:$B$506, B66)>1, "DUPLICATE", "OK") -> OK
A67: SKU-1061 | B67: Stainless Steel Stock Pot Compact | C67: Kitchen | D67: MATCHED | E67: 56.69 | F67: 60.67 | G67: -3.98 | H67: -0.0702 | I67: CRITICAL Negative margin | J67: 19 | K67: 15 | L67: 459 | M67: 478 | N67: HEALTHY AVAILABILITY Internal available stock | O67: Fulfill in-house | P67: =IF(COUNTIF($B$2:$B$506, B67)>1, "DUPLICATE", "OK") -> OK
A68: SKU-1062 | B68: Velvet Cushion Cover - Red | C68: Home | D68: MATCHED | E68: 26.34 | F68: 8 | G68: 18.34 | H68: 0.6963 | I68: MARGIN OK | J68: 27 | K68: 15 | L68: 274 | M68: 301 | N68: HEALTHY AVAILABILITY Internal available stock | O68: Fulfill in-house | P68: =IF(COUNTIF($B$2:$B$506, B68)>1, "DUPLICATE", "OK") -> OK
A69: SKU-1063 | B69: Woven Laundry Basket Large | C69: Home | D69: MATCHED | E69: 42.85 | F69: 20.13 | G69: 22.72 | H69: 0.5302 | I69: MARGIN OK | J69: 30 | K69: 15 | L69: 0 | M69: 30 | N69: HEALTHY AVAILABILITY Internal available stock | O69: Fulfill in-house | P69: =IF(COUNTIF($B$2:$B$506, B69)>1, "DUPLICATE", "OK") -> OK
A70: SKU-1064 | B70: Ninja Professional Blender Classic - Rose | C70: Kitchen | D70: MATCHED | E70: 118.06 | F70: 72.3 | G70: 45.76 | H70: 0.3876 | I70: MARGIN OK | J70: 32 | K70: 15 | L70: 206 | M70: 238 | N70: HEALTHY AVAILABILITY Internal available stock | O70: Fulfill in-house | P70: =IF(COUNTIF($B$2:$B$506, B70)>1, "DUPLICATE", "OK") -> OK
A71: SKU-1065 | B71: Glass Photo Frame 20x25 Set of 2 - Gray | C71: Home | D71: MATCHED | E71: 27.88 | F71: 8.73 | G71: 19.15 | H71: 0.6869 | I71: MARGIN OK | J71: 68 | K71: 15 | L71: 165 | M71: 233 | N71: HEALTHY AVAILABILITY Internal available stock | O71: Fulfill in-house | P71: =IF(COUNTIF($B$2:$B$506, B71)>1, "DUPLICATE", "OK") -> OK
...

Sheet 02_Operational_Analysis
B2: Margin Audit
B3: Margin Health Status | C3: SKU Count | D3: Supplier Stock Units | E3: Total Supplier Cost | F3: Total Retail Value | G3: Net Profit/Loss | H3: Avg Margin %
B4: MARGIN OK | C4: =COUNTIF(tbl_InventorySupplier[margin_health_status], B4) -> 483 | D4: =SUMIFS(tbl_InventorySupplier[supplier_stock], tbl_InventorySupplier[margin_health_status], B4) -> 116575 | E4: {=SUMPRODUCT((tbl_InventorySupplier[margin_health_status]=B4) * tbl_InventorySupplier[supplier_stock] * tbl_InventorySupplier[current_supplier_cost])} -> 4362546.3 | F4: {=SUMPRODUCT((tbl_InventorySupplier[margin_health_status]=B4) * tbl_InventorySupplier[supplier_stock] * N(+tbl_InventorySupplier[retail_price]))} -> 8871134.3 | G4: =F4 - E4 -> 4508588 | H4: =IF(F4=0, "N/A", G4 / F4) -> 0.50823129
B5: CRITICAL Negative margin | C5: =COUNTIF(tbl_InventorySupplier[margin_health_status], B5) -> 9 | D5: =SUMIFS(tbl_InventorySupplier[supplier_stock], tbl_InventorySupplier[margin_health_status], B5) -> 2168 | E5: {=SUMPRODUCT((tbl_InventorySupplier[margin_health_status]=B5) * tbl_InventorySupplier[supplier_stock] * tbl_InventorySupplier[current_supplier_cost])} -> 135344.38 | F5: {=SUMPRODUCT((tbl_InventorySupplier[margin_health_status]=B5) * tbl_InventorySupplier[supplier_stock] * N(+tbl_InventorySupplier[retail_price]))} -> 118446.39 | G5: =F5 - E5 -> -16897.99 | H5: =IF(F5=0, "N/A", G5 / F5) -> -0.14266361
B6: N/A Missing price data | C6: =COUNTIF(tbl_InventorySupplier[margin_health_status], B6) -> 13 | D6: =SUMIFS(tbl_InventorySupplier[supplier_stock], tbl_InventorySupplier[margin_health_status], B6) -> 2621 | E6: {=SUMPRODUCT((tbl_InventorySupplier[margin_health_status]=B6) * tbl_InventorySupplier[supplier_stock] * tbl_InventorySupplier[current_supplier_cost])} -> 78516.16 | F6: {=SUMPRODUCT((tbl_InventorySupplier[margin_health_status]=B6) * tbl_InventorySupplier[supplier_stock] * N(+tbl_InventorySupplier[retail_price]))} -> 0 | G6: =F6 - E6 -> -78516.16 | H6: =IF(F6=0, "N/A", G6 / F6) -> N/A
B7: Total | C7: =SUBTOTAL(109,C4:C6) -> 505 | D7: =SUBTOTAL(109,D4:D6) -> 121364 | E7: =SUBTOTAL(109,E4:E6) -> 4576406.8 | F7: =SUBTOTAL(109,F4:F6) -> 8989580.7 | G7: =SUBTOTAL(109,tbl_MarginAudit[Net Profit/Loss]) -> 4413173.9 | H7: =G7/F7 -> 0.49092099
B9: Stock Health
B10: Stock Health Status | C10: SKU Count | D10: Internal Stock Units | E10: Internal Stock Value | F10: Supplier Stock Units | G10: Recommended Route
B11: HEALTHY AVAILABILITY Internal available stock | C11: =COUNTIF(tbl_InventorySupplier[stock_health_status], B11) -> 423 | D11: =SUMIF(tbl_InventorySupplier[stock_health_status], B11, tbl_InventorySupplier[internal_stock]) -> 24905 | E11: {=SUMPRODUCT((tbl_InventorySupplier[stock_health_status]=B11)*(tbl_InventorySupplier[internal_stock])*(tbl_InventorySupplier[current_supplier_cost]))} -> 966003.58 | F11: =SUMIF(tbl_InventorySupplier[stock_health_status], B11, tbl_InventorySupplier[supplier_stock]) -> 101843 | G11: Fulfill in-house
B12: WARNING Below reorder point - reorder available from Supplier | C12: =COUNTIF(tbl_InventorySupplier[stock_health_status], B12) -> 70 | D12: =SUMIF(tbl_InventorySupplier[stock_health_status], B12, tbl_InventorySupplier[internal_stock]) -> 533 | E12: {=SUMPRODUCT((tbl_InventorySupplier[stock_health_status]=B12)*(tbl_InventorySupplier[internal_stock])*(tbl_InventorySupplier[current_supplier_cost]))} -> 19337.28 | F12: =SUMIF(tbl_InventorySupplier[stock_health_status], B12, tbl_InventorySupplier[supplier_stock]) -> 17373 | G12: Fulfill in-house
B13: CRITICAL Internal stockout - reorder available from Supplier | C13: =COUNTIF(tbl_InventorySupplier[stock_health_status], B13) -> 12 | D13: =SUMIF(tbl_InventorySupplier[stock_health_status], B13, tbl_InventorySupplier[internal_stock]) -> 0 | E13: {=SUMPRODUCT((tbl_InventorySupplier[stock_health_status]=B13)*(tbl_InventorySupplier[internal_stock])*(tbl_InventorySupplier[current_supplier_cost]))} -> 0 | F13: =SUMIF(tbl_InventorySupplier[stock_health_status], B13, tbl_InventorySupplier[supplier_stock]) -> 2148 | G13: Fulfill via dropship
B14: Total | C14: =SUBTOTAL(109,C11:C13) -> 505 | D14: =SUBTOTAL(109,D11:D13) -> 25438 | E14: =SUBTOTAL(109,E11:E13) -> 985340.86 | F14: =SUBTOTAL(109,F11:F13) -> 121364
B16: Category Margin
B17: Product Category | C17: SKU Count | D17: Internal Stock Value | E17: Weight on Internal Stock % | F17: Weighted Margin % | G17: Reorder Alert SKUs | H17: Average Ticket Price
B18: Books | C18: =COUNTIF(tbl_InventorySupplier[category], B18) -> 58 | D18: {=SUMPRODUCT((tbl_InventorySupplier[category]=B18)*(tbl_InventorySupplier[internal_stock])*(tbl_InventorySupplier[current_supplier_cost]))} -> 37003.29 | E18: =D18 / $D$28 -> 0.037553796 | F18: {=1 - (D18 / SUMPRODUCT((tbl_InventorySupplier[category]=B18) * tbl_InventorySupplier[internal_stock] * tbl_InventorySupplier[retail_price]))} -> 0.46258696 | G18: {=SUMPRODUCT((tbl_InventorySupplier[category]=B18) * (tbl_InventorySupplier[internal_stock] <= tbl_InventorySupplier[reorder_point]))} -> 9 | H18: =AVERAGEIFS(tbl_InventorySupplier[retail_price], tbl_InventorySupplier[category], B18, tbl_InventorySupplier[retail_price], ">0") -> 25.725088
B19: Electronics | C19: =COUNTIF(tbl_InventorySupplier[category], B19) -> 68 | D19: {=SUMPRODUCT((tbl_InventorySupplier[category]=B19)*(tbl_InventorySupplier[internal_stock])*(tbl_InventorySupplier[current_supplier_cost]))} -> 358841.8 | E19: =D19 / $D$28 -> 0.36418037 | F19: {=1 - (D19 / SUMPRODUCT((tbl_InventorySupplier[category]=B19) * tbl_InventorySupplier[internal_stock] * tbl_InventorySupplier[retail_price]))} -> 0.56151859 | G19: {=SUMPRODUCT((tbl_InventorySupplier[category]=B19) * (tbl_InventorySupplier[internal_stock] <= tbl_InventorySupplier[reorder_point]))} -> 14 | H19: =AVERAGEIFS(tbl_InventorySupplier[retail_price], tbl_InventorySupplier[category], B19, tbl_InventorySupplier[retail_price], ">0") -> 250.97
B20: Toys | C20: =COUNTIF(tbl_InventorySupplier[category], B20) -> 61 | D20: {=SUMPRODUCT((tbl_InventorySupplier[category]=B20)*(tbl_InventorySupplier[internal_stock])*(tbl_InventorySupplier[current_supplier_cost]))} -> 69226.83 | E20: =D20 / $D$28 -> 0.070256733 | F20: {=1 - (D20 / SUMPRODUCT((tbl_InventorySupplier[category]=B20) * tbl_InventorySupplier[internal_stock] * tbl_InventorySupplier[retail_price]))} -> 0.42049158 | G20: {=SUMPRODUCT((tbl_InventorySupplier[category]=B20) * (tbl_InventorySupplier[internal_stock] <= tbl_InventorySupplier[reorder_point]))} -> 7 | H20: =AVERAGEIFS(tbl_InventorySupplier[retail_price], tbl_InventorySupplier[category], B20, tbl_InventorySupplier[retail_price], ">0") -> 39.797966
B21: Home | C21: =COUNTIF(tbl_InventorySupplier[category], B21) -> 72 | D21: {=SUMPRODUCT((tbl_InventorySupplier[category]=B21)*(tbl_InventorySupplier[internal_stock])*(tbl_InventorySupplier[current_supplier_cost]))} -> 94309.85 | E21: =D21 / $D$28 -> 0.095712919 | F21: {=1 - (D21 / SUMPRODUCT((tbl_InventorySupplier[category]=B21) * tbl_InventorySupplier[internal_stock] * tbl_InventorySupplier[retail_price]))} -> 0.46161474 | G21: {=SUMPRODUCT((tbl_InventorySupplier[category]=B21) * (tbl_InventorySupplier[internal_stock] <= tbl_InventorySupplier[reorder_point]))} -> 9 | H21: =AVERAGEIFS(tbl_InventorySupplier[retail_price], tbl_InventorySupplier[category], B21, tbl_InventorySupplier[retail_price], ">0") -> 48.430714
B22: Clothing | C22: =COUNTIF(tbl_InventorySupplier[category], B22) -> 66 | D22: {=SUMPRODUCT((tbl_InventorySupplier[category]=B22)*(tbl_InventorySupplier[internal_stock])*(tbl_InventorySupplier[current_supplier_cost]))} -> 122334.88 | E22: =D22 / $D$28 -> 0.12415488 | F22: {=1 - (D22 / SUMPRODUCT((tbl_InventorySupplier[category]=B22) * tbl_InventorySupplier[internal_stock] * tbl_InventorySupplier[retail_price]))} -> 0.43767419 | G22: {=SUMPRODUCT((tbl_InventorySupplier[category]=B22) * (tbl_InventorySupplier[internal_stock] <= tbl_InventorySupplier[reorder_point]))} -> 12 | H22: =AVERAGEIFS(tbl_InventorySupplier[retail_price], tbl_InventorySupplier[category], B22, tbl_InventorySupplier[retail_price], ">0") -> 58.985606
B23: Sports | C23: =COUNTIF(tbl_InventorySupplier[category], B23) -> 46 | D23: {=SUMPRODUCT((tbl_InventorySupplier[category]=B23)*(tbl_InventorySupplier[internal_stock])*(tbl_InventorySupplier[current_supplier_cost]))} -> 69474.6 | E23: =D23 / $D$28 -> 0.070508189 | F23: {=1 - (D23 / SUMPRODUCT((tbl_InventorySupplier[category]=B23) * tbl_InventorySupplier[internal_stock] * tbl_InventorySupplier[retail_price]))} -> 0.49408489 | G23: {=SUMPRODUCT((tbl_InventorySupplier[category]=B23) * (tbl_InventorySupplier[internal_stock] <= tbl_InventorySupplier[reorder_point]))} -> 6 | H23: =AVERAGEIFS(tbl_InventorySupplier[retail_price], tbl_InventorySupplier[category], B23, tbl_InventorySupplier[retail_price], ">0") -> 53.639111
B24: Kitchen | C24: =COUNTIF(tbl_InventorySupplier[category], B24) -> 73 | D24: {=SUMPRODUCT((tbl_InventorySupplier[category]=B24)*(tbl_InventorySupplier[internal_stock])*(tbl_InventorySupplier[current_supplier_cost]))} -> 114336.85 | E24: =D24 / $D$28 -> 0.11603787 | F24: {=1 - (D24 / SUMPRODUCT((tbl_InventorySupplier[category]=B24) * tbl_InventorySupplier[internal_stock] * tbl_InventorySupplier[retail_price]))} -> 0.48378075 | G24: {=SUMPRODUCT((tbl_InventorySupplier[category]=B24) * (tbl_InventorySupplier[internal_stock] <= tbl_InventorySupplier[reorder_point]))} -> 12 | H24: =AVERAGEIFS(tbl_InventorySupplier[retail_price], tbl_InventorySupplier[category], B24, tbl_InventorySupplier[retail_price], ">0") -> 60.321507
B25: Beauty | C25: =COUNTIF(tbl_InventorySupplier[category], B25) -> 51 | D25: {=SUMPRODUCT((tbl_InventorySupplier[category]=B25)*(tbl_InventorySupplier[internal_stock])*(tbl_InventorySupplier[current_supplier_cost]))} -> 113315.17 | E25: =D25 / $D$28 -> 0.11500099 | F25: {=1 - (D25 / SUMPRODUCT((tbl_InventorySupplier[category]=B25) * tbl_InventorySupplier[internal_stock] * tbl_InventorySupplier[retail_price]))} -> 0.43810889 | G25: {=SUMPRODUCT((tbl_InventorySupplier[category]=B25) * (tbl_InventorySupplier[internal_stock] <= tbl_InventorySupplier[reorder_point]))} -> 8 | H25: =AVERAGEIFS(tbl_InventorySupplier[retail_price], tbl_InventorySupplier[category], B25, tbl_InventorySupplier[retail_price], ">0") -> 74.756531
B26: Unknown | C26: =COUNTIF(tbl_InventorySupplier[category], B26) -> 5 | D26: {=SUMPRODUCT((tbl_InventorySupplier[category]=B26)*(tbl_InventorySupplier[internal_stock])*(tbl_InventorySupplier[current_supplier_cost]))} -> 6497.59 | E26: =D26 / $D$28 -> 0.0065942561 | F26: {=1 - (D26 / SUMPRODUCT((tbl_InventorySupplier[category]=B26) * tbl_InventorySupplier[internal_stock] * tbl_InventorySupplier[retail_price]))} -> 0.50174913 | G26: {=SUMPRODUCT((tbl_InventorySupplier[category]=B26) * (tbl_InventorySupplier[internal_stock] <= tbl_InventorySupplier[reorder_point]))} -> 0 | H26: =AVERAGEIFS(tbl_InventorySupplier[retail_price], tbl_InventorySupplier[category], B26, tbl_InventorySupplier[retail_price], ">0") -> 45.572
B27: (Blanks) | C27: =COUNTBLANK(tbl_InventorySupplier[category]) -> 5 | D27: {=SUMPRODUCT((tbl_InventorySupplier[category]="")*(tbl_InventorySupplier[internal_stock])*(tbl_InventorySupplier[current_supplier_cost]))} -> 0 | E27: =D27 / $D$28 -> 0 | F27: {=1 - (D27 / SUMPRODUCT((tbl_InventorySupplier[category]="") * tbl_InventorySupplier[internal_stock] * tbl_InventorySupplier[retail_price]))} -> #DIV/0! | G27: {=SUMPRODUCT((tbl_InventorySupplier[category]="") * (tbl_InventorySupplier[internal_stock] <= tbl_InventorySupplier[reorder_point]))} -> 5 | H27: =AVERAGEIFS(tbl_InventorySupplier[retail_price], tbl_InventorySupplier[category], "", tbl_InventorySupplier[retail_price], ">0") -> #DIV/0!
B28: Total | C28: =SUBTOTAL(109,C18:C27) -> 505 | D28: =SUBTOTAL(109,D18:D27) -> 985340.86 | G28: =SUBTOTAL(109,G18:G27) -> 82
B30: Category Leverage Status
B31: Product Category | C31: Internal Stock Units | D31: Supplier Stock Units | E31: Supplier Leverage Ratio | F31: Leverage Status
B32: Books | C32: =SUMIFS(tbl_InventorySupplier[internal_stock], tbl_InventorySupplier[category], B32) -> 2906 | D32: =SUMIFS(tbl_InventorySupplier[supplier_stock], tbl_InventorySupplier[category], B32) -> 13656 | E32: =IF(C32=0, "N/A", D32 / C32) -> 4.6992429 | F32: =IF(E32 ="N/A", "N/A", IF(E32>=5, "Maximum Leverage", IF(E32>=4.5, "High Potential", "Moderate Leverage"))) -> High Potential
B33: Electronics | C33: =SUMIFS(tbl_InventorySupplier[internal_stock], tbl_InventorySupplier[category], B33) -> 3165 | D33: =SUMIFS(tbl_InventorySupplier[supplier_stock], tbl_InventorySupplier[category], B33) -> 15563 | E33: =IF(C33=0, "N/A", D33 / C33) -> 4.9172196 | F33: =IF(E33 ="N/A", "N/A", IF(E33>=5, "Maximum Leverage", IF(E33>=4.5, "High Potential", "Moderate Leverage"))) -> High Potential
B34: Toys | C34: =SUMIFS(tbl_InventorySupplier[internal_stock], tbl_InventorySupplier[category], B34) -> 3082 | D34: =SUMIFS(tbl_InventorySupplier[supplier_stock], tbl_InventorySupplier[category], B34) -> 16187 | E34: =IF(C34=0, "N/A", D34 / C34) -> 5.252109 | F34: =IF(E34 ="N/A", "N/A", IF(E34>=5, "Maximum Leverage", IF(E34>=4.5, "High Potential", "Moderate Leverage"))) -> Maximum Leverage
B35: Home | C35: =SUMIFS(tbl_InventorySupplier[internal_stock], tbl_InventorySupplier[category], B35) -> 3901 | D35: =SUMIFS(tbl_InventorySupplier[supplier_stock], tbl_InventorySupplier[category], B35) -> 17695 | E35: =IF(C35=0, "N/A", D35 / C35) -> 4.5360164 | F35: =IF(E35 ="N/A", "N/A", IF(E35>=5, "Maximum Leverage", IF(E35>=4.5, "High Potential", "Moderate Leverage"))) -> High Potential
B36: Clothing | C36: =SUMIFS(tbl_InventorySupplier[internal_stock], tbl_InventorySupplier[category], B36) -> 3435 | D36: =SUMIFS(tbl_InventorySupplier[supplier_stock], tbl_InventorySupplier[category], B36) -> 14551 | E36: =IF(C36=0, "N/A", D36 / C36) -> 4.236099 | F36: =IF(E36 ="N/A", "N/A", IF(E36>=5, "Maximum Leverage", IF(E36>=4.5, "High Potential", "Moderate Leverage"))) -> Moderate Leverage
B37: Sports | C37: =SUMIFS(tbl_InventorySupplier[internal_stock], tbl_InventorySupplier[category], B37) -> 2621 | D37: =SUMIFS(tbl_InventorySupplier[supplier_stock], tbl_InventorySupplier[category], B37) -> 11837 | E37: =IF(C37=0, "N/A", D37 / C37) -> 4.5162152 | F37: =IF(E37 ="N/A", "N/A", IF(E37>=5, "Maximum Leverage", IF(E37>=4.5, "High Potential", "Moderate Leverage"))) -> High Potential
B38: Kitchen | C38: =SUMIFS(tbl_InventorySupplier[internal_stock], tbl_InventorySupplier[category], B38) -> 3492 | D38: =SUMIFS(tbl_InventorySupplier[supplier_stock], tbl_InventorySupplier[category], B38) -> 17086 | E38: =IF(C38=0, "N/A", D38 / C38) -> 4.8928981 | F38: =IF(E38 ="N/A", "N/A", IF(E38>=5, "Maximum Leverage", IF(E38>=4.5, "High Potential", "Moderate Leverage"))) -> High Potential
B39: Beauty | C39: =SUMIFS(tbl_InventorySupplier[internal_stock], tbl_InventorySupplier[category], B39) -> 2495 | D39: =SUMIFS(tbl_InventorySupplier[supplier_stock], tbl_InventorySupplier[category], B39) -> 12766 | E39: =IF(C39=0, "N/A", D39 / C39) -> 5.1166333 | F39: =IF(E39 ="N/A", "N/A", IF(E39>=5, "Maximum Leverage", IF(E39>=4.5, "High Potential", "Moderate Leverage"))) -> Maximum Leverage
B40: Unknown | C40: =SUMIFS(tbl_InventorySupplier[internal_stock], tbl_InventorySupplier[category], B40) -> 341 | D40: =SUMIFS(tbl_InventorySupplier[supplier_stock], tbl_InventorySupplier[category], B40) -> 1443 | E40: =IF(C40=0, "N/A", D40 / C40) -> 4.2316716 | F40: =IF(E40 ="N/A", "N/A", IF(E40>=5, "Maximum Leverage", IF(E40>=4.5, "High Potential", "Moderate Leverage"))) -> Moderate Leverage
B41: (Blanks) | C41: =SUMIFS(tbl_InventorySupplier[internal_stock], tbl_InventorySupplier[category], "") -> 0 | D41: =SUMIFS(tbl_InventorySupplier[supplier_stock], tbl_InventorySupplier[category], "") -> 580 | E41: =IF(C41=0, "N/A", D41 / C41) -> N/A | F41: =IF(E41 ="N/A", "N/A", IF(E41>=5, "Maximum Leverage", IF(E41>=4.5, "High Potential", "Moderate Leverage"))) -> N/A
B42: Total
B44: Category Price Tier
B45: Product Category | C45: Min Retail Price | D45: Average Ticket Price | E45: Max Retail Price | F45: Price Tier
...

Sheet 03_Executive_Dashboard
H1: EXECUTIVE SUPPLY CHAIN & MARGIN DASHBOARD
B2: INTERNAL STOCK VALUE | G2: SUPPLIER STOCK VALUE | L2: POTENTIAL NET PROFIT | Q2: EXECUTIVE REORDER BUDGET | V2: SAVED LIQUIDITY
B3: ='02_Operational_Analysis'!E14 -> 985340.86 | G3: ='02_Operational_Analysis'!G74 -> 4576406.8 | L3: ='02_Operational_Analysis'!G7 -> 4413173.9 | Q3: ='02_Operational_Analysis'!H68 -> 268503.6 | V3: ='02_Operational_Analysis'!F62 - '02_Operational_Analysis'!H68 -> 18970.12
B4: =TEXT('02_Operational_Analysis'!D14, "#,##0") & " in-house stock units" -> 25,438 in-house stock units | G4: =TEXT('02_Operational_Analysis'!F74, "#,##0") & " supplier stock units" -> 121,364 supplier stock units | L4: ="AVG margin: " & TEXT('02_Operational_Analysis'!H7, "0.00%") -> AVG margin: 49.09% | Q4: ="Order Fulfillment Capacity: " & TEXT('02_Operational_Analysis'!G68, "0.00%") -> Order Fulfillment Capacity: 86.38% | V4: Protected by supplier constraints
F28: DATA QUALITY & OPERATIONAL HEALTH AUDIT
C32: Overall Health Category | F32: SKU Count | G32: Internal Stock Units | I32: Internal Stock Value (€) | K32: Supplier Stock Units | M32: Supplier Stock Value (€) | O32: Recommended Action
C34: DUPLICATE: Duplicate Product Name | F34: =COUNTIF(tbl_InventorySupplier[duplicate_name], "DUPLICATE") -> 16 | G34: =SUMIFS(tbl_InventorySupplier[internal_stock], tbl_InventorySupplier[duplicate_name], "DUPLICATE") -> 915 | I34: {=SUMPRODUCT((tbl_InventorySupplier[duplicate_name]="DUPLICATE") * tbl_InventorySupplier[internal_stock] * tbl_InventorySupplier[current_supplier_cost])} -> 57582.85 | K34: =SUMIFS(tbl_InventorySupplier[supplier_stock], tbl_InventorySupplier[duplicate_name], "DUPLICATE") -> 3525 | M34: {=SUMPRODUCT((tbl_InventorySupplier[duplicate_name]="DUPLICATE") * tbl_InventorySupplier[supplier_stock] * tbl_InventorySupplier[current_supplier_cost])} -> 207787.07 | O34: Reconcile product name records (different SKUs)
C35: UNMATCHED: Supplier Only | F35: =COUNTIF(tbl_InventorySupplier[catalog_integration_status], "SUPPLIER ONLY") -> 5 | G35: =SUMIFS(tbl_InventorySupplier[internal_stock], tbl_InventorySupplier[catalog_integration_status], "SUPPLIER ONLY") -> 0 | I35: {=SUMPRODUCT((tbl_InventorySupplier[catalog_integration_status]="SUPPLIER ONLY") * tbl_InventorySupplier[internal_stock] * tbl_InventorySupplier[current_supplier_cost])} -> 0 | K35: =SUMIFS(tbl_InventorySupplier[supplier_stock], tbl_InventorySupplier[catalog_integration_status], "SUPPLIER ONLY") -> 580 | M35: {=SUMPRODUCT((tbl_InventorySupplier[catalog_integration_status]="SUPPLIER ONLY") * tbl_InventorySupplier[supplier_stock] * tbl_InventorySupplier[current_supplier_cost])} -> 42183.29 | O35: Map codes in the e-commerce catalog
C36: CRITICAL: Negative Margin | F36: =COUNTIF(tbl_InventorySupplier[margin_health_status], "CRITICAL Negative margin") -> 9 | G36: =SUMIFS(tbl_InventorySupplier[internal_stock], tbl_InventorySupplier[margin_health_status], "CRITICAL Negative margin") -> 461 | I36: {=SUMPRODUCT((tbl_InventorySupplier[margin_health_status]="CRITICAL Negative margin") * tbl_InventorySupplier[internal_stock] * tbl_InventorySupplier[current_supplier_cost])} -> 27956.61 | K36: =SUMIFS(tbl_InventorySupplier[supplier_stock], tbl_InventorySupplier[margin_health_status], "CRITICAL Negative margin") -> 2168 | M36: {=SUMPRODUCT((tbl_InventorySupplier[margin_health_status]="CRITICAL Negative margin") * tbl_InventorySupplier[supplier_stock] * tbl_InventorySupplier[current_supplier_cost])} -> 135344.38 | O36: Suspend sales and update price list
C37: WARNING: Missing Price | F37: =COUNTIF(tbl_InventorySupplier[margin_health_status], "N/A Missing price data") -> 13 | G37: =SUMIFS(tbl_InventorySupplier[internal_stock], tbl_InventorySupplier[margin_health_status], "N/A Missing price data") -> 450 | I37: {=SUMPRODUCT((tbl_InventorySupplier[margin_health_status]="N/A Missing price data") * tbl_InventorySupplier[internal_stock] * tbl_InventorySupplier[current_supplier_cost])} -> 7439.55 | K37: =SUMIFS(tbl_InventorySupplier[supplier_stock], tbl_InventorySupplier[margin_health_status], "N/A Missing price data") -> 2621 | M37: {=SUMPRODUCT((tbl_InventorySupplier[margin_health_status]="N/A Missing price data") * tbl_InventorySupplier[supplier_stock] * tbl_InventorySupplier[current_supplier_cost])} -> 78516.16 | O37: Enter missing retail price
C38: WARNING: Internal Stockout | F38: =COUNTIFS(tbl_InventorySupplier[stock_health_status], "*stockout*") -> 12 | G38: =SUMIFS(tbl_InventorySupplier[internal_stock], tbl_InventorySupplier[stock_health_status], "*stockout*") -> 0 | I38: {=SUMPRODUCT(ISNUMBER(SEARCH("stockout", tbl_InventorySupplier[stock_health_status])) * tbl_InventorySupplier[internal_stock] * tbl_InventorySupplier[current_supplier_cost])} -> 0 | K38: =SUMIFS(tbl_InventorySupplier[supplier_stock], tbl_InventorySupplier[stock_health_status], "*stockout*") -> 2148 | M38: {=SUMPRODUCT(ISNUMBER(SEARCH("stockout", tbl_InventorySupplier[stock_health_status])) * tbl_InventorySupplier[supplier_stock] * tbl_InventorySupplier[current_supplier_cost])} -> 83866.43 | O38: Enable dropshipping routing
C39: ATTENTION: Low Stock (Full Cvg) | F39: {=SUMPRODUCT((tbl_InventorySupplier[internal_stock] <= tbl_InventorySupplier[reorder_point]) * (tbl_InventorySupplier[supplier_stock] >= (100 - tbl_InventorySupplier[internal_stock])))} -> 61 | G39: {=SUMPRODUCT((tbl_InventorySupplier[internal_stock] <= tbl_InventorySupplier[reorder_point]) * (tbl_InventorySupplier[supplier_stock] >= (100 - tbl_InventorySupplier[internal_stock])) * tbl_InventorySupplier[internal_stock])} -> 421 | I39: {=SUMPRODUCT((tbl_InventorySupplier[internal_stock] <= tbl_InventorySupplier[reorder_point]) * (tbl_InventorySupplier[supplier_stock] >= (100 - tbl_InventorySupplier[internal_stock])) * tbl_InventorySupplier[internal_stock] * tbl_InventorySupplier[current_supplier_cost])} -> 15408.16 | K39: {=SUMPRODUCT((tbl_InventorySupplier[internal_stock] <= tbl_InventorySupplier[reorder_point]) * (tbl_InventorySupplier[supplier_stock] >= (100 - tbl_InventorySupplier[internal_stock])) * tbl_InventorySupplier[supplier_stock])} -> 18577 | M39: {=SUMPRODUCT((tbl_InventorySupplier[internal_stock] <= tbl_InventorySupplier[reorder_point]) * (tbl_InventorySupplier[supplier_stock] >= (100 - tbl_InventorySupplier[internal_stock])) * tbl_InventorySupplier[supplier_stock] * tbl_InventorySupplier[current_supplier_cost])} -> 789157.55 | O39: Activate 100% Purchase Order routing
C40: ATTENTION: Low Stock (Partial Cvg) | F40: {=SUMPRODUCT((tbl_InventorySupplier[internal_stock] <= tbl_InventorySupplier[reorder_point]) * (tbl_InventorySupplier[supplier_stock] < (100 - tbl_InventorySupplier[internal_stock])))} -> 21 | G40: {=SUMPRODUCT((tbl_InventorySupplier[internal_stock] <= tbl_InventorySupplier[reorder_point]) * (tbl_InventorySupplier[supplier_stock] < (100 - tbl_InventorySupplier[internal_stock])) * tbl_InventorySupplier[internal_stock])} -> 112 | I40: {=SUMPRODUCT((tbl_InventorySupplier[internal_stock] <= tbl_InventorySupplier[reorder_point]) * (tbl_InventorySupplier[supplier_stock] < (100 - tbl_InventorySupplier[internal_stock])) * tbl_InventorySupplier[internal_stock] * tbl_InventorySupplier[current_supplier_cost])} -> 3929.12 | K40: {=SUMPRODUCT((tbl_InventorySupplier[internal_stock] <= tbl_InventorySupplier[reorder_point]) * (tbl_InventorySupplier[supplier_stock] < (100 - tbl_InventorySupplier[internal_stock])) * tbl_InventorySupplier[supplier_stock])} -> 944 | M40: {=SUMPRODUCT((tbl_InventorySupplier[internal_stock] <= tbl_InventorySupplier[reorder_point]) * (tbl_InventorySupplier[supplier_stock] < (100 - tbl_InventorySupplier[internal_stock])) * tbl_InventorySupplier[supplier_stock] * tbl_InventorySupplier[current_supplier_cost])} -> 40890.76 | O40: Order max 944 units + Backorder follow-up
C41: HEALTHY: OK | F41: =COUNTA(tbl_InventorySupplier[consolidated_sku]) - SUM(F34:F40) -> 368 | G41: =SUM(tbl_InventorySupplier[internal_stock])-SUM(G34:H40) -> 23079 | I41: {=SUM(tbl_InventorySupplier[internal_stock]*tbl_InventorySupplier[current_supplier_cost])-SUM(I34:J40)} -> 873024.57 | K41: =SUM(tbl_InventorySupplier[supplier_stock])-SUM(K34:L40) -> 90801 | M41: {=SUM(tbl_InventorySupplier[supplier_stock] * tbl_InventorySupplier[current_supplier_cost])-SUM(M34:N40)} -> 3198661.2 | O41: Standard full-scale operations
C43: total | F43: =SUM(F34:F41) -> 505 | G43: =SUM(G34:H41) -> 25438 | I43: =SUM(I34:J41) -> 985340.86 | K43: =SUM(K34:L41) -> 121364 | M43: =SUM(M34:N41) -> 4576406.8

Sheet PivotData
A3: Product Category | B3: Sum of Internal Stock Units | C3: Sum of Supplier Stock Units | E3: Margin Health Status | F3: Sum of Net Profit/Loss
A4: Beauty | B4: 2495 | C4: 12766 | E4: MARGIN OK | F4: 4508588
A5: Books | B5: 2906 | C5: 13656 | E5: CRITICAL Negative margin | F5: -16897.99
A6: Clothing | B6: 3435 | C6: 14551 | E6: N/A Missing price data | F6: -78516.16
A7: Electronics | B7: 3165 | C7: 15563 | E7: Grand Total | F7: 4413173.9
A8: Home | B8: 3901 | C8: 17695
A9: Kitchen | B9: 3492 | C9: 17086
A10: Sports | B10: 2621 | C10: 11837 | E10: Fulfillment Feasibility Tier | F10: Sum of Theoretical Reorder Need | G10: Sum of Fulfillable Units
A11: Toys | B11: 3082 | C11: 16187 | E11: Full Coverage | F11: 5679 | G11: 5679
A12: Unknown | B12: 341 | C12: 1443 | E12: Partial Coverage | F12: 1988 | G12: 944
A13: (Blanks) | B13: 0 | C13: 580 | E13: Grand Total | F13: 7667 | G13: 6623
A14: Grand Total | B14: 25438 | C14: 121364
A17: Product Category | B17: Sum of Internal Stock Value | E17: Stock Health Status | F17: Sum of SKU Count
A18: Beauty | B18: 113315.17 | E18: HEALTHY AVAILABILITY | F18: 423
A19: Books | B19: 37003.29 | E19: WARNING Below reorder point | F19: 70
A20: Clothing | B20: 122334.88 | E20: CRITICAL Internal stockout | F20: 12
A21: Electronics | B21: 358841.8 | E21: Grand Total | F21: 505
A22: Home | B22: 94309.85
A23: Kitchen | B23: 114336.85
A24: Sports | B24: 69474.6 | E24: VALUE | F24: HEALTHY | G24: NO HEALTHY
A25: Toys | B25: 69226.83 | E25: SKU Count | F25: ='03_Executive_Dashboard'!F41 -> 368 | G25: =SUM('03_Executive_Dashboard'!F34:F40) -> 137
A26: Unknown | B26: 6497.59 | E26: Internal Stock Units | F26: ='03_Executive_Dashboard'!G41 -> 23079 | G26: =SUM('03_Executive_Dashboard'!G34:H40) -> 2359
A27: (Blanks) | B27: 0 | E27: Internal Stock Value (€) | F27: ='03_Executive_Dashboard'!I41 -> 873024.57 | G27: =SUM('03_Executive_Dashboard'!I34:J40) -> 112316.29
A28: Grand Total | B28: 985340.86 | E28: Supplier Stock Units | F28: ='03_Executive_Dashboard'!K41 -> 90801 | G28: =SUM('03_Executive_Dashboard'!K34:L40) -> 30563
E29: Supplier Stock Value (€) | F29: ='03_Executive_Dashboard'!M41 -> 3198661.2 | G29: =SUM('03_Executive_Dashboard'!M34:N40) -> 1377745.6
